2018-06-04 15:11:12,427 ERROR: Exception on /install_android_app [GET] [in /home/ubuntu/anaconda3/lib/python3.6/site-packages/flask/app.py:1560]
Traceback (most recent call last):
  File "/home/ubuntu/anaconda3/lib/python3.6/site-packages/flask/app.py", line 1982, in wsgi_app
    response = self.full_dispatch_request()
  File "/home/ubuntu/anaconda3/lib/python3.6/site-packages/flask/app.py", line 1614, in full_dispatch_request
    rv = self.handle_user_exception(e)
  File "/home/ubuntu/anaconda3/lib/python3.6/site-packages/flask/app.py", line 1517, in handle_user_exception
    reraise(exc_type, exc_value, tb)
  File "/home/ubuntu/anaconda3/lib/python3.6/site-packages/flask/_compat.py", line 33, in reraise
    raise value
  File "/home/ubuntu/anaconda3/lib/python3.6/site-packages/flask/app.py", line 1612, in full_dispatch_request
    rv = self.dispatch_request()
  File "/home/ubuntu/anaconda3/lib/python3.6/site-packages/flask/app.py", line 1598, in dispatch_request
    return self.view_functions[rule.endpoint](**req.view_args)
  File "/home/ubuntu/github/python/buttonApp_2/app/routes.py", line 230, in installAndroidApp
    send_file('/static/app-release.apk', as_attachment=True)
  File "/home/ubuntu/anaconda3/lib/python3.6/site-packages/flask/helpers.py", line 549, in send_file
    file = open(filename, 'rb')
FileNotFoundError: [Errno 2] No such file or directory: '/static/app-release.apk'
2018-06-04 15:12:45,842 INFO: Two Button startup [in /home/ubuntu/github/python/buttonApp_2/app/__init__.py:47]
2018-06-04 15:13:10,320 ERROR: Exception on /install_android_app [GET] [in /home/ubuntu/anaconda3/lib/python3.6/site-packages/flask/app.py:1560]
Traceback (most recent call last):
  File "/home/ubuntu/anaconda3/lib/python3.6/site-packages/flask/app.py", line 1982, in wsgi_app
    response = self.full_dispatch_request()
  File "/home/ubuntu/anaconda3/lib/python3.6/site-packages/flask/app.py", line 1615, in full_dispatch_request
    return self.finalize_request(rv)
  File "/home/ubuntu/anaconda3/lib/python3.6/site-packages/flask/app.py", line 1630, in finalize_request
    response = self.make_response(rv)
  File "/home/ubuntu/anaconda3/lib/python3.6/site-packages/flask/app.py", line 1725, in make_response
    raise ValueError('View function did not return a response')
ValueError: View function did not return a response
2018-06-04 15:17:20,414 INFO: Two Button startup [in /home/ubuntu/github/python/buttonApp_2/app/__init__.py:47]
2018-06-04 15:24:23,413 INFO: Two Button startup [in /home/ubuntu/github/python/buttonApp_2/app/__init__.py:47]
2018-06-04 15:28:28,824 INFO: Two Button startup [in /home/ubuntu/github/python/buttonApp_2/app/__init__.py:47]
2018-06-04 18:34:59,354 INFO: Two Button startup [in /home/ubuntu/github/python/buttonApp_2/app/__init__.py:47]
2018-06-04 18:37:12,215 INFO: Two Button startup [in /home/ubuntu/github/python/buttonApp_2/app/__init__.py:47]
2018-06-05 00:20:32,621 INFO: Two Button startup [in /home/ubuntu/github/python/buttonApp_2/app/__init__.py:47]
2018-06-05 10:24:08,784 INFO: Two Button startup [in /home/ubuntu/github/python/buttonApp_2/app/__init__.py:47]
2018-06-05 10:24:23,700 ERROR: Exception on /plot [GET] [in /home/ubuntu/anaconda3/lib/python3.6/site-packages/flask/app.py:1560]
Traceback (most recent call last):
  File "/home/ubuntu/anaconda3/lib/python3.6/site-packages/flask/app.py", line 1982, in wsgi_app
    response = self.full_dispatch_request()
  File "/home/ubuntu/anaconda3/lib/python3.6/site-packages/flask/app.py", line 1614, in full_dispatch_request
    rv = self.handle_user_exception(e)
  File "/home/ubuntu/anaconda3/lib/python3.6/site-packages/flask/app.py", line 1517, in handle_user_exception
    reraise(exc_type, exc_value, tb)
  File "/home/ubuntu/anaconda3/lib/python3.6/site-packages/flask/_compat.py", line 33, in reraise
    raise value
  File "/home/ubuntu/anaconda3/lib/python3.6/site-packages/flask/app.py", line 1612, in full_dispatch_request
    rv = self.dispatch_request()
  File "/home/ubuntu/anaconda3/lib/python3.6/site-packages/flask/app.py", line 1598, in dispatch_request
    return self.view_functions[rule.endpoint](**req.view_args)
  File "/home/ubuntu/github/python/buttonApp_2/app/routes.py", line 197, in plot
    script, div = components(plot)
NameError: name 'components' is not defined
2018-06-05 10:36:53,607 INFO: Two Button startup [in /home/ubuntu/github/python/buttonApp_2/app/__init__.py:47]
2018-06-05 10:39:50,737 INFO: Two Button startup [in /home/ubuntu/github/python/buttonApp_2/app/__init__.py:47]
2018-06-05 10:42:55,701 INFO: Two Button startup [in /home/ubuntu/github/python/buttonApp_2/app/__init__.py:47]
2018-06-05 10:43:29,335 INFO: Two Button startup [in /home/ubuntu/github/python/buttonApp_2/app/__init__.py:47]
2018-06-05 11:58:59,117 INFO: Two Button startup [in /home/ubuntu/github/python/buttonApp_2/app/__init__.py:47]
2018-06-05 12:00:33,325 INFO: Two Button startup [in /home/ubuntu/github/python/buttonApp_2/app/__init__.py:47]
2018-06-05 12:01:22,115 INFO: Two Button startup [in /home/ubuntu/github/python/buttonApp_2/app/__init__.py:47]
2018-06-05 17:03:27,813 INFO: Two Button startup [in /home/ubuntu/github/python/buttonApp_2/app/__init__.py:47]
2018-06-05 17:03:42,294 INFO: Two Button startup [in /home/ubuntu/github/python/buttonApp_2/app/__init__.py:47]
2018-06-05 17:03:48,182 ERROR: Exception on /plot2 [GET] [in /home/ubuntu/anaconda3/lib/python3.6/site-packages/flask/app.py:1560]
Traceback (most recent call last):
  File "/home/ubuntu/anaconda3/lib/python3.6/site-packages/flask/app.py", line 1982, in wsgi_app
    response = self.full_dispatch_request()
  File "/home/ubuntu/anaconda3/lib/python3.6/site-packages/flask/app.py", line 1614, in full_dispatch_request
    rv = self.handle_user_exception(e)
  File "/home/ubuntu/anaconda3/lib/python3.6/site-packages/flask/app.py", line 1517, in handle_user_exception
    reraise(exc_type, exc_value, tb)
  File "/home/ubuntu/anaconda3/lib/python3.6/site-packages/flask/_compat.py", line 33, in reraise
    raise value
  File "/home/ubuntu/anaconda3/lib/python3.6/site-packages/flask/app.py", line 1612, in full_dispatch_request
    rv = self.dispatch_request()
  File "/home/ubuntu/anaconda3/lib/python3.6/site-packages/flask/app.py", line 1598, in dispatch_request
    return self.view_functions[rule.endpoint](**req.view_args)
  File "/home/ubuntu/github/python/buttonApp_2/app/routes.py", line 156, in plot2
    plot.vbar(x=timeStrings, top=[1 for i in range(len(timeStrings))])
TypeError: vbar() missing 1 required positional argument: 'width'
2018-06-05 17:04:19,204 INFO: Two Button startup [in /home/ubuntu/github/python/buttonApp_2/app/__init__.py:47]
2018-06-05 17:08:49,092 INFO: Two Button startup [in /home/ubuntu/github/python/buttonApp_2/app/__init__.py:47]
2018-06-05 17:08:53,289 ERROR: Exception on /plot2 [GET] [in /home/ubuntu/anaconda3/lib/python3.6/site-packages/flask/app.py:1560]
Traceback (most recent call last):
  File "/home/ubuntu/anaconda3/lib/python3.6/site-packages/flask/app.py", line 1982, in wsgi_app
    response = self.full_dispatch_request()
  File "/home/ubuntu/anaconda3/lib/python3.6/site-packages/flask/app.py", line 1614, in full_dispatch_request
    rv = self.handle_user_exception(e)
  File "/home/ubuntu/anaconda3/lib/python3.6/site-packages/flask/app.py", line 1517, in handle_user_exception
    reraise(exc_type, exc_value, tb)
  File "/home/ubuntu/anaconda3/lib/python3.6/site-packages/flask/_compat.py", line 33, in reraise
    raise value
  File "/home/ubuntu/anaconda3/lib/python3.6/site-packages/flask/app.py", line 1612, in full_dispatch_request
    rv = self.dispatch_request()
  File "/home/ubuntu/anaconda3/lib/python3.6/site-packages/flask/app.py", line 1598, in dispatch_request
    return self.view_functions[rule.endpoint](**req.view_args)
  File "/home/ubuntu/github/python/buttonApp_2/app/routes.py", line 164, in plot2
    this_color = colors[i]
IndexError: list index out of range
2018-06-05 17:09:40,782 INFO: Two Button startup [in /home/ubuntu/github/python/buttonApp_2/app/__init__.py:47]
2018-06-05 17:15:49,461 INFO: Two Button startup [in /home/ubuntu/github/python/buttonApp_2/app/__init__.py:47]
2018-06-05 17:15:53,966 ERROR: Exception on /plot2 [GET] [in /home/ubuntu/anaconda3/lib/python3.6/site-packages/flask/app.py:1560]
Traceback (most recent call last):
  File "/home/ubuntu/anaconda3/lib/python3.6/site-packages/flask/app.py", line 1982, in wsgi_app
    response = self.full_dispatch_request()
  File "/home/ubuntu/anaconda3/lib/python3.6/site-packages/flask/app.py", line 1614, in full_dispatch_request
    rv = self.handle_user_exception(e)
  File "/home/ubuntu/anaconda3/lib/python3.6/site-packages/flask/app.py", line 1517, in handle_user_exception
    reraise(exc_type, exc_value, tb)
  File "/home/ubuntu/anaconda3/lib/python3.6/site-packages/flask/_compat.py", line 33, in reraise
    raise value
  File "/home/ubuntu/anaconda3/lib/python3.6/site-packages/flask/app.py", line 1612, in full_dispatch_request
    rv = self.dispatch_request()
  File "/home/ubuntu/anaconda3/lib/python3.6/site-packages/flask/app.py", line 1598, in dispatch_request
    return self.view_functions[rule.endpoint](**req.view_args)
  File "/home/ubuntu/github/python/buttonApp_2/app/routes.py", line 172, in plot2
    p.xaxis.ticker = a
NameError: name 'p' is not defined
2018-06-05 17:16:11,121 INFO: Two Button startup [in /home/ubuntu/github/python/buttonApp_2/app/__init__.py:47]
