2018-06-01 19:04:42,882 ERROR: Exception on /plot [GET] [in /home/ubuntu/anaconda3/lib/python3.6/site-packages/flask/app.py:1560]
Traceback (most recent call last):
  File "/home/ubuntu/anaconda3/lib/python3.6/site-packages/flask/app.py", line 1982, in wsgi_app
    response = self.full_dispatch_request()
  File "/home/ubuntu/anaconda3/lib/python3.6/site-packages/flask/app.py", line 1614, in full_dispatch_request
    rv = self.handle_user_exception(e)
  File "/home/ubuntu/anaconda3/lib/python3.6/site-packages/flask/app.py", line 1517, in handle_user_exception
    reraise(exc_type, exc_value, tb)
  File "/home/ubuntu/anaconda3/lib/python3.6/site-packages/flask/_compat.py", line 33, in reraise
    raise value
  File "/home/ubuntu/anaconda3/lib/python3.6/site-packages/flask/app.py", line 1612, in full_dispatch_request
    rv = self.dispatch_request()
  File "/home/ubuntu/anaconda3/lib/python3.6/site-packages/flask/app.py", line 1598, in dispatch_request
    return self.view_functions[rule.endpoint](**req.view_args)
  File "/home/ubuntu/github/python/buttonApp_2/app/routes.py", line 157, in plot
    deltas = timedeltas(results)
  File "/home/ubuntu/github/python/buttonApp_2/app/routes.py", line 68, in timedeltas
    datetimes = [string_to_datetime(thisTimeStamp[1]) for thisTimeStamp in timestampData]
  File "/home/ubuntu/github/python/buttonApp_2/app/routes.py", line 68, in <listcomp>
    datetimes = [string_to_datetime(thisTimeStamp[1]) for thisTimeStamp in timestampData]
  File "/home/ubuntu/github/python/buttonApp_2/app/routes.py", line 64, in string_to_datetime
    year,month,day,hour,minute,second,millisecond = [int(i) for i in datetime_string.split('.')]
AttributeError: 'int' object has no attribute 'split'
2018-06-01 19:05:40,312 ERROR: Exception on /plot [GET] [in /home/ubuntu/anaconda3/lib/python3.6/site-packages/flask/app.py:1560]
Traceback (most recent call last):
  File "/home/ubuntu/anaconda3/lib/python3.6/site-packages/flask/app.py", line 1982, in wsgi_app
    response = self.full_dispatch_request()
  File "/home/ubuntu/anaconda3/lib/python3.6/site-packages/flask/app.py", line 1614, in full_dispatch_request
    rv = self.handle_user_exception(e)
  File "/home/ubuntu/anaconda3/lib/python3.6/site-packages/flask/app.py", line 1517, in handle_user_exception
    reraise(exc_type, exc_value, tb)
  File "/home/ubuntu/anaconda3/lib/python3.6/site-packages/flask/_compat.py", line 33, in reraise
    raise value
  File "/home/ubuntu/anaconda3/lib/python3.6/site-packages/flask/app.py", line 1612, in full_dispatch_request
    rv = self.dispatch_request()
  File "/home/ubuntu/anaconda3/lib/python3.6/site-packages/flask/app.py", line 1598, in dispatch_request
    return self.view_functions[rule.endpoint](**req.view_args)
  File "/home/ubuntu/github/python/buttonApp_2/app/routes.py", line 157, in plot
    deltas = timedeltas(results)
  File "/home/ubuntu/github/python/buttonApp_2/app/routes.py", line 68, in timedeltas
    datetimes = [string_to_datetime(thisTimeStamp[1]) for thisTimeStamp in timestampData]
  File "/home/ubuntu/github/python/buttonApp_2/app/routes.py", line 68, in <listcomp>
    datetimes = [string_to_datetime(thisTimeStamp[1]) for thisTimeStamp in timestampData]
  File "/home/ubuntu/github/python/buttonApp_2/app/routes.py", line 64, in string_to_datetime
    year,month,day,hour,minute,second,millisecond = [int(i) for i in datetime_string.split('.')]
AttributeError: 'int' object has no attribute 'split'
2018-06-01 19:09:17,175 ERROR: Exception on /plot [GET] [in /home/ubuntu/anaconda3/lib/python3.6/site-packages/flask/app.py:1560]
Traceback (most recent call last):
  File "/home/ubuntu/anaconda3/lib/python3.6/site-packages/flask/app.py", line 1982, in wsgi_app
    response = self.full_dispatch_request()
  File "/home/ubuntu/anaconda3/lib/python3.6/site-packages/flask/app.py", line 1614, in full_dispatch_request
    rv = self.handle_user_exception(e)
  File "/home/ubuntu/anaconda3/lib/python3.6/site-packages/flask/app.py", line 1517, in handle_user_exception
    reraise(exc_type, exc_value, tb)
  File "/home/ubuntu/anaconda3/lib/python3.6/site-packages/flask/_compat.py", line 33, in reraise
    raise value
  File "/home/ubuntu/anaconda3/lib/python3.6/site-packages/flask/app.py", line 1612, in full_dispatch_request
    rv = self.dispatch_request()
  File "/home/ubuntu/anaconda3/lib/python3.6/site-packages/flask/app.py", line 1598, in dispatch_request
    return self.view_functions[rule.endpoint](**req.view_args)
  File "/home/ubuntu/github/python/buttonApp_2/app/routes.py", line 157, in plot
    deltas = timedeltas(results)
  File "/home/ubuntu/github/python/buttonApp_2/app/routes.py", line 68, in timedeltas
    datetimes = [string_to_datetime(thisTimeStamp[1]) for thisTimeStamp in timestampData]
  File "/home/ubuntu/github/python/buttonApp_2/app/routes.py", line 68, in <listcomp>
    datetimes = [string_to_datetime(thisTimeStamp[1]) for thisTimeStamp in timestampData]
  File "/home/ubuntu/github/python/buttonApp_2/app/routes.py", line 64, in string_to_datetime
    year,month,day,hour,minute,second,millisecond = [int(i) for i in datetime_string.split('.')]
AttributeError: 'int' object has no attribute 'split'
2018-06-01 19:09:22,711 INFO: Two Button startup [in /home/ubuntu/github/python/buttonApp_2/app/__init__.py:47]
2018-06-01 19:09:37,889 ERROR: Exception on /download [GET] [in /home/ubuntu/anaconda3/lib/python3.6/site-packages/flask/app.py:1560]
Traceback (most recent call last):
  File "/home/ubuntu/anaconda3/lib/python3.6/site-packages/flask/app.py", line 1982, in wsgi_app
    response = self.full_dispatch_request()
  File "/home/ubuntu/anaconda3/lib/python3.6/site-packages/flask/app.py", line 1614, in full_dispatch_request
    rv = self.handle_user_exception(e)
  File "/home/ubuntu/anaconda3/lib/python3.6/site-packages/flask/app.py", line 1517, in handle_user_exception
    reraise(exc_type, exc_value, tb)
  File "/home/ubuntu/anaconda3/lib/python3.6/site-packages/flask/_compat.py", line 33, in reraise
    raise value
  File "/home/ubuntu/anaconda3/lib/python3.6/site-packages/flask/app.py", line 1612, in full_dispatch_request
    rv = self.dispatch_request()
  File "/home/ubuntu/anaconda3/lib/python3.6/site-packages/flask/app.py", line 1598, in dispatch_request
    return self.view_functions[rule.endpoint](**req.view_args)
  File "/home/ubuntu/github/python/buttonApp_2/app/routes.py", line 140, in download
    all_data = ['timestamp, button_id, text_info'] + [str(i[1],i[2],i[4]) for i in user_data_all_get(user_id)]
  File "/home/ubuntu/github/python/buttonApp_2/app/routes.py", line 140, in <listcomp>
    all_data = ['timestamp, button_id, text_info'] + [str(i[1],i[2],i[4]) for i in user_data_all_get(user_id)]
TypeError: str() argument 2 must be str, not int
2018-06-01 19:10:13,802 INFO: Two Button startup [in /home/ubuntu/github/python/buttonApp_2/app/__init__.py:47]
2018-06-01 19:42:25,762 INFO: Two Button startup [in /home/ubuntu/github/python/buttonApp_2/app/__init__.py:47]
2018-06-01 19:43:01,369 INFO: Two Button startup [in /home/ubuntu/github/python/buttonApp_2/app/__init__.py:47]
2018-06-01 19:54:00,087 INFO: Two Button startup [in /home/ubuntu/github/python/buttonApp_2/app/__init__.py:47]
2018-06-01 19:54:09,688 ERROR: Exception on /plot [GET] [in /home/ubuntu/anaconda3/lib/python3.6/site-packages/flask/app.py:1560]
Traceback (most recent call last):
  File "/home/ubuntu/anaconda3/lib/python3.6/site-packages/flask/app.py", line 1982, in wsgi_app
    response = self.full_dispatch_request()
  File "/home/ubuntu/anaconda3/lib/python3.6/site-packages/flask/app.py", line 1614, in full_dispatch_request
    rv = self.handle_user_exception(e)
  File "/home/ubuntu/anaconda3/lib/python3.6/site-packages/flask/app.py", line 1517, in handle_user_exception
    reraise(exc_type, exc_value, tb)
  File "/home/ubuntu/anaconda3/lib/python3.6/site-packages/flask/_compat.py", line 33, in reraise
    raise value
  File "/home/ubuntu/anaconda3/lib/python3.6/site-packages/flask/app.py", line 1612, in full_dispatch_request
    rv = self.dispatch_request()
  File "/home/ubuntu/anaconda3/lib/python3.6/site-packages/flask/app.py", line 1598, in dispatch_request
    return self.view_functions[rule.endpoint](**req.view_args)
  File "/home/ubuntu/github/python/buttonApp_2/app/routes.py", line 172, in plot
    events_in_secs = [string_to_datetime(thisTimeStamp[1]).total_seconds() for thisTimeStamp in timestampData]
NameError: name 'timestampData' is not defined
2018-06-01 19:55:20,907 INFO: Two Button startup [in /home/ubuntu/github/python/buttonApp_2/app/__init__.py:47]
2018-06-01 19:55:27,856 ERROR: Exception on /plot [GET] [in /home/ubuntu/anaconda3/lib/python3.6/site-packages/flask/app.py:1560]
Traceback (most recent call last):
  File "/home/ubuntu/anaconda3/lib/python3.6/site-packages/flask/app.py", line 1982, in wsgi_app
    response = self.full_dispatch_request()
  File "/home/ubuntu/anaconda3/lib/python3.6/site-packages/flask/app.py", line 1614, in full_dispatch_request
    rv = self.handle_user_exception(e)
  File "/home/ubuntu/anaconda3/lib/python3.6/site-packages/flask/app.py", line 1517, in handle_user_exception
    reraise(exc_type, exc_value, tb)
  File "/home/ubuntu/anaconda3/lib/python3.6/site-packages/flask/_compat.py", line 33, in reraise
    raise value
  File "/home/ubuntu/anaconda3/lib/python3.6/site-packages/flask/app.py", line 1612, in full_dispatch_request
    rv = self.dispatch_request()
  File "/home/ubuntu/anaconda3/lib/python3.6/site-packages/flask/app.py", line 1598, in dispatch_request
    return self.view_functions[rule.endpoint](**req.view_args)
  File "/home/ubuntu/github/python/buttonApp_2/app/routes.py", line 172, in plot
    events_in_secs = [string_to_datetime(thisTimeStamp[1]).total_seconds() for thisTimeStamp in results]
  File "/home/ubuntu/github/python/buttonApp_2/app/routes.py", line 172, in <listcomp>
    events_in_secs = [string_to_datetime(thisTimeStamp[1]).total_seconds() for thisTimeStamp in results]
AttributeError: 'datetime.datetime' object has no attribute 'total_seconds'
2018-06-01 19:58:59,919 INFO: Two Button startup [in /home/ubuntu/github/python/buttonApp_2/app/__init__.py:47]
