2018-06-05 17:16:14,072 ERROR: Exception on /plot2 [GET] [in /home/ubuntu/anaconda3/lib/python3.6/site-packages/flask/app.py:1560]
Traceback (most recent call last):
  File "/home/ubuntu/anaconda3/lib/python3.6/site-packages/flask/app.py", line 1982, in wsgi_app
    response = self.full_dispatch_request()
  File "/home/ubuntu/anaconda3/lib/python3.6/site-packages/flask/app.py", line 1614, in full_dispatch_request
    rv = self.handle_user_exception(e)
  File "/home/ubuntu/anaconda3/lib/python3.6/site-packages/flask/app.py", line 1517, in handle_user_exception
    reraise(exc_type, exc_value, tb)
  File "/home/ubuntu/anaconda3/lib/python3.6/site-packages/flask/_compat.py", line 33, in reraise
    raise value
  File "/home/ubuntu/anaconda3/lib/python3.6/site-packages/flask/app.py", line 1612, in full_dispatch_request
    rv = self.dispatch_request()
  File "/home/ubuntu/anaconda3/lib/python3.6/site-packages/flask/app.py", line 1598, in dispatch_request
    return self.view_functions[rule.endpoint](**req.view_args)
  File "/home/ubuntu/github/python/buttonApp_2/app/routes.py", line 181, in plot2
    p.xaxis.major_label_orientation = -pi/4
NameError: name 'p' is not defined
2018-06-05 17:16:32,090 INFO: Two Button startup [in /home/ubuntu/github/python/buttonApp_2/app/__init__.py:47]
2018-06-05 17:26:42,581 INFO: Two Button startup [in /home/ubuntu/github/python/buttonApp_2/app/__init__.py:47]
2018-06-05 17:31:28,426 INFO: Two Button startup [in /home/ubuntu/github/python/buttonApp_2/app/__init__.py:47]
2018-06-05 17:31:33,642 ERROR: Exception on /plot2 [GET] [in /home/ubuntu/anaconda3/lib/python3.6/site-packages/flask/app.py:1560]
Traceback (most recent call last):
  File "/home/ubuntu/anaconda3/lib/python3.6/site-packages/flask/app.py", line 1982, in wsgi_app
    response = self.full_dispatch_request()
  File "/home/ubuntu/anaconda3/lib/python3.6/site-packages/flask/app.py", line 1614, in full_dispatch_request
    rv = self.handle_user_exception(e)
  File "/home/ubuntu/anaconda3/lib/python3.6/site-packages/flask/app.py", line 1517, in handle_user_exception
    reraise(exc_type, exc_value, tb)
  File "/home/ubuntu/anaconda3/lib/python3.6/site-packages/flask/_compat.py", line 33, in reraise
    raise value
  File "/home/ubuntu/anaconda3/lib/python3.6/site-packages/flask/app.py", line 1612, in full_dispatch_request
    rv = self.dispatch_request()
  File "/home/ubuntu/anaconda3/lib/python3.6/site-packages/flask/app.py", line 1598, in dispatch_request
    return self.view_functions[rule.endpoint](**req.view_args)
  File "/home/ubuntu/github/python/buttonApp_2/app/routes.py", line 177, in plot2
    plot.xaxis.major_label_overrides = timeStrings
  File "/home/ubuntu/anaconda3/lib/python3.6/site-packages/bokeh/util/plot_utils.py", line 9, in __setattr__
    setattr(x, attr, value)
  File "/home/ubuntu/anaconda3/lib/python3.6/site-packages/bokeh/core/has_props.py", line 263, in __setattr__
    super(HasProps, self).__setattr__(name, value)
  File "/home/ubuntu/anaconda3/lib/python3.6/site-packages/bokeh/core/property/descriptors.py", line 503, in __set__
    self._internal_set(obj, value, setter=setter)
  File "/home/ubuntu/anaconda3/lib/python3.6/site-packages/bokeh/core/property/descriptors.py", line 724, in _internal_set
    value = self.property.prepare_value(obj, self.name, value)
  File "/home/ubuntu/anaconda3/lib/python3.6/site-packages/bokeh/core/property/bases.py", line 278, in prepare_value
    raise e
  File "/home/ubuntu/anaconda3/lib/python3.6/site-packages/bokeh/core/property/bases.py", line 271, in prepare_value
    self.validate(value)
  File "/home/ubuntu/anaconda3/lib/python3.6/site-packages/bokeh/core/properties.py", line 1305, in validate
    raise ValueError("expected an element of %s, got %r" % (self, value))
ValueError: expected an element of Dict(Either(Float, String), String), got ['2018.06.03.09.30.12.433', '2018.06.03.09.30.13.001', '2018.06.03.09.30.13.666', '2018.06.03.09.30.14.218', '2018.06.03.09.30.14.935', '2018.06.03.09.30.15.573', '2018.06.03.09.31.39.113', '2018.06.03.09.31.39.888', '2018.06.03.09.31.40.597', '2018.06.03.09.31.41.148', '2018.06.03.09.31.41.716', '2018.06.03.09.31.44.709', '2018.06.03.09.31.45.208', '2018.06.03.09.31.52.941', '2018.06.03.09.31.54.129', '2018.06.03.09.31.55.597', '2018.06.03.09.31.56.119', '2018.06.03.09.33.17.527', '2018.06.03.09.33.18.848', '2018.06.03.09.33.20.102', '2018.06.03.10.31.01.558', '2018.06.03.10.31.03.356', '2018.06.03.10.31.04.836', '2018.06.03.12.40.52.029', '2018.06.03.16.54.46.523', '2018.06.03.16.54.47.390', '2018.06.03.16.54.47.973', '2018.06.03.16.54.48.691', '2018.06.03.16.57.25.838', '2018.06.03.16.57.27.051', '2018.06.03.16.57.27.568', '2018.06.04.06.36.23.492', '2018.06.04.06.36.24.242', '2018.06.04.06.36.24.821', '2018.06.04.06.36.25.336', '2018.06.04.14.52.08.608', '2018.06.05.06.50.45.048']
2018-06-05 17:33:28,111 INFO: Two Button startup [in /home/ubuntu/github/python/buttonApp_2/app/__init__.py:47]
2018-06-05 17:36:19,978 INFO: Two Button startup [in /home/ubuntu/github/python/buttonApp_2/app/__init__.py:47]
2018-06-05 17:57:40,019 INFO: Two Button startup [in /home/ubuntu/github/python/buttonApp_2/app/__init__.py:47]
2018-06-05 19:05:38,752 INFO: Two Button startup [in /home/ubuntu/github/python/buttonApp_2/app/__init__.py:47]
2018-06-05 20:51:30,365 INFO: Two Button startup [in /home/ubuntu/github/python/buttonApp_2/app/__init__.py:47]
2018-06-05 20:51:55,914 INFO: Two Button startup [in /home/ubuntu/github/python/buttonApp_2/app/__init__.py:47]
2018-06-05 20:52:18,772 INFO: Two Button startup [in /home/ubuntu/github/python/buttonApp_2/app/__init__.py:47]
2018-06-05 20:56:23,869 INFO: Two Button startup [in /home/ubuntu/github/python/buttonApp_2/app/__init__.py:47]
2018-06-05 20:56:27,294 ERROR: Exception on /plot [GET] [in /home/ubuntu/anaconda3/lib/python3.6/site-packages/flask/app.py:1560]
Traceback (most recent call last):
  File "/home/ubuntu/anaconda3/lib/python3.6/site-packages/flask/app.py", line 1982, in wsgi_app
    response = self.full_dispatch_request()
  File "/home/ubuntu/anaconda3/lib/python3.6/site-packages/flask/app.py", line 1614, in full_dispatch_request
    rv = self.handle_user_exception(e)
  File "/home/ubuntu/anaconda3/lib/python3.6/site-packages/flask/app.py", line 1517, in handle_user_exception
    reraise(exc_type, exc_value, tb)
  File "/home/ubuntu/anaconda3/lib/python3.6/site-packages/flask/_compat.py", line 33, in reraise
    raise value
  File "/home/ubuntu/anaconda3/lib/python3.6/site-packages/flask/app.py", line 1612, in full_dispatch_request
    rv = self.dispatch_request()
  File "/home/ubuntu/anaconda3/lib/python3.6/site-packages/flask/app.py", line 1598, in dispatch_request
    return self.view_functions[rule.endpoint](**req.view_args)
  File "/home/ubuntu/github/python/buttonApp_2/app/routes.py", line 189, in plot
    plot.add_layout(Title(text="Events: Blue = Button 0, Red = Button 1 "), 'above')
NameError: name 'Title' is not defined
2018-06-05 20:57:01,681 INFO: Two Button startup [in /home/ubuntu/github/python/buttonApp_2/app/__init__.py:47]
2018-06-05 20:59:58,228 INFO: Two Button startup [in /home/ubuntu/github/python/buttonApp_2/app/__init__.py:47]
2018-06-05 21:00:10,316 INFO: Two Button startup [in /home/ubuntu/github/python/buttonApp_2/app/__init__.py:47]
2018-06-05 21:00:20,587 INFO: Two Button startup [in /home/ubuntu/github/python/buttonApp_2/app/__init__.py:47]
2018-06-05 21:00:41,250 INFO: Two Button startup [in /home/ubuntu/github/python/buttonApp_2/app/__init__.py:47]
2018-06-05 21:01:55,617 INFO: Two Button startup [in /home/ubuntu/github/python/buttonApp_2/app/__init__.py:47]
2018-06-05 21:02:38,794 INFO: Two Button startup [in /home/ubuntu/github/python/buttonApp_2/app/__init__.py:47]
2018-06-09 16:40:32,470 INFO: Two Button startup [in /home/ubuntu/github/python/buttonApp_2/app/__init__.py:47]
2018-06-10 15:46:18,897 ERROR: Exception on /plot [GET] [in /home/ubuntu/anaconda3/lib/python3.6/site-packages/flask/app.py:1560]
Traceback (most recent call last):
  File "/home/ubuntu/anaconda3/lib/python3.6/site-packages/flask/app.py", line 1982, in wsgi_app
    response = self.full_dispatch_request()
  File "/home/ubuntu/anaconda3/lib/python3.6/site-packages/flask/app.py", line 1614, in full_dispatch_request
    rv = self.handle_user_exception(e)
  File "/home/ubuntu/anaconda3/lib/python3.6/site-packages/flask/app.py", line 1517, in handle_user_exception
    reraise(exc_type, exc_value, tb)
  File "/home/ubuntu/anaconda3/lib/python3.6/site-packages/flask/_compat.py", line 33, in reraise
    raise value
  File "/home/ubuntu/anaconda3/lib/python3.6/site-packages/flask/app.py", line 1612, in full_dispatch_request
    rv = self.dispatch_request()
  File "/home/ubuntu/anaconda3/lib/python3.6/site-packages/flask/app.py", line 1598, in dispatch_request
    return self.view_functions[rule.endpoint](**req.view_args)
  File "/home/ubuntu/github/python/buttonApp_2/app/routes.py", line 167, in plot
    this_color = colors[i]
IndexError: list index out of range
2018-06-10 15:48:37,357 ERROR: Exception on /plot [GET] [in /home/ubuntu/anaconda3/lib/python3.6/site-packages/flask/app.py:1560]
Traceback (most recent call last):
  File "/home/ubuntu/anaconda3/lib/python3.6/site-packages/flask/app.py", line 1982, in wsgi_app
    response = self.full_dispatch_request()
  File "/home/ubuntu/anaconda3/lib/python3.6/site-packages/flask/app.py", line 1614, in full_dispatch_request
    rv = self.handle_user_exception(e)
  File "/home/ubuntu/anaconda3/lib/python3.6/site-packages/flask/app.py", line 1517, in handle_user_exception
    reraise(exc_type, exc_value, tb)
  File "/home/ubuntu/anaconda3/lib/python3.6/site-packages/flask/_compat.py", line 33, in reraise
    raise value
  File "/home/ubuntu/anaconda3/lib/python3.6/site-packages/flask/app.py", line 1612, in full_dispatch_request
    rv = self.dispatch_request()
  File "/home/ubuntu/anaconda3/lib/python3.6/site-packages/flask/app.py", line 1598, in dispatch_request
    return self.view_functions[rule.endpoint](**req.view_args)
  File "/home/ubuntu/github/python/buttonApp_2/app/routes.py", line 167, in plot
    this_color = colors[i]
IndexError: list index out of range
